[2024-03-06 20:49:11,238][flwr][INFO] - Starting Flower simulation, config: ServerConfig(num_rounds=10, round_timeout=None)
[2024-03-06 20:49:14,936][flwr][INFO] - Flower VCE: Ray initialized with resources: {'object_store_memory': 15453498163.0, 'node:127.0.0.1': 1.0, 'memory': 30906996327.0, 'node:__internal_head__': 1.0, 'CPU': 24.0, 'accelerator_type:G': 1.0, 'GPU': 1.0}
[2024-03-06 20:49:14,936][flwr][INFO] - Optimize your simulation with Flower VCE: https://flower.dev/docs/framework/how-to-run-simulations.html
[2024-03-06 20:49:14,936][flwr][INFO] - No `client_resources` specified. Using minimal resources for clients.
[2024-03-06 20:49:14,937][flwr][INFO] - Flower VCE: Resources for each Virtual Client: {'num_cpus': 1, 'num_gpus': 0.0}
[2024-03-06 20:49:14,950][flwr][INFO] - Flower VCE: Creating VirtualClientEngineActorPool with 24 actors
[2024-03-06 20:49:14,951][flwr][INFO] - Initializing global parameters
[2024-03-06 20:49:14,951][flwr][INFO] - Requesting initial parameters from one random client
[2024-03-06 20:49:19,322][flwr][ERROR] - Traceback (most recent call last):
  File "C:\Users\Guddu\anaconda3\envs\capstone\Lib\site-packages\flwr\simulation\ray_transport\ray_client_proxy.py", line 151, in _submit_job
    res, updated_context = self.actor_pool.get_client_result(self.cid, timeout)
                           ^^^^^^^^^^^^^^^^^^^^^^^^^^^^^^^^^^^^^^^^^^^^^^^^^^^^
  File "C:\Users\Guddu\anaconda3\envs\capstone\Lib\site-packages\flwr\simulation\ray_transport\ray_actor.py", line 425, in get_client_result
    return self._fetch_future_result(cid)
           ^^^^^^^^^^^^^^^^^^^^^^^^^^^^^^
  File "C:\Users\Guddu\anaconda3\envs\capstone\Lib\site-packages\flwr\simulation\ray_transport\ray_actor.py", line 306, in _fetch_future_result
    res_cid, res, updated_context = ray.get(
                                    ^^^^^^^^
  File "C:\Users\Guddu\anaconda3\envs\capstone\Lib\site-packages\ray\_private\auto_init_hook.py", line 22, in auto_init_wrapper
    return fn(*args, **kwargs)
           ^^^^^^^^^^^^^^^^^^^
  File "C:\Users\Guddu\anaconda3\envs\capstone\Lib\site-packages\ray\_private\client_mode_hook.py", line 103, in wrapper
    return func(*args, **kwargs)
           ^^^^^^^^^^^^^^^^^^^^^
  File "C:\Users\Guddu\anaconda3\envs\capstone\Lib\site-packages\ray\_private\worker.py", line 2624, in get
    raise value.as_instanceof_cause()
ray.exceptions.RayTaskError(ClientException): [36mray::DefaultActor.run()[39m (pid=23928, ip=127.0.0.1, actor_id=a82a3640cc207c23333ef1b701000000, repr=<flwr.simulation.ray_transport.ray_actor.DefaultActor object at 0x000002360037C350>)
                                           ^^^^^^^^^^^^^^
  File "J:\Rehaan's College Project\fed_tutorial_next\client.py", line 97, in client_fn
    return FlowerClient(
           ^^^^^^^^^^^^^
  File "J:\Rehaan's College Project\fed_tutorial_next\client.py", line 22, in __init__
    self.model = Net(num_classes)
                 ^^^^^^^^^^^^^^^^
  File "J:\Rehaan's College Project\fed_tutorial_next\model.py", line 23, in __init__
    self.conv1 = nn.Conv2d(3, 32, 3)
    ^^^^^^^^^^
  File "C:\Users\Guddu\anaconda3\envs\capstone\Lib\site-packages\torch\nn\modules\module.py", line 1716, in __setattr__
    raise AttributeError(
AttributeError: cannot assign module before Module.__init__() call

The above exception was the direct cause of the following exception:

[36mray::DefaultActor.run()[39m (pid=23928, ip=127.0.0.1, actor_id=a82a3640cc207c23333ef1b701000000, repr=<flwr.simulation.ray_transport.ray_actor.DefaultActor object at 0x000002360037C350>)
  File "python\ray\_raylet.pyx", line 1807, in ray._raylet.execute_task
  File "python\ray\_raylet.pyx", line 1908, in ray._raylet.execute_task
  File "python\ray\_raylet.pyx", line 1813, in ray._raylet.execute_task
  File "python\ray\_raylet.pyx", line 1754, in ray._raylet.execute_task.function_executor
  File "C:\Users\Guddu\anaconda3\envs\capstone\Lib\site-packages\ray\_private\function_manager.py", line 726, in actor_method_executor
    return method(__ray_actor, *args, **kwargs)
           ^^^^^^^^^^^^^^^^^^^^^^^^^^^^^^^^^^^^
  File "C:\Users\Guddu\anaconda3\envs\capstone\Lib\site-packages\ray\util\tracing\tracing_helper.py", line 467, in _resume_span
    return method(self, *_args, **_kwargs)
           ^^^^^^^^^^^^^^^^^^^^^^^^^^^^^^^
  File "C:\Users\Guddu\anaconda3\envs\capstone\Lib\site-packages\flwr\simulation\ray_transport\ray_actor.py", line 90, in run
    raise ClientException(str(message)) from ex
flwr.simulation.ray_transport.ray_actor.ClientException: 
>>>>>>>A ClientException occurred.('\n\tSomething went wrong when running your client run.\n\tClient 12 crashed when the DefaultActor was running its run.\n\tException triggered on the client side: Traceback (most recent call last):\n  File "C:\\Users\\Guddu\\anaconda3\\envs\\capstone\\Lib\\site-packages\\flwr\\simulation\\ray_transport\\ray_actor.py", line 72, in run\n    client = check_clientfn_returns_client(client_fn(cid))\n                                           ^^^^^^^^^^^^^^\n  File "J:\\Rehaan\'s College Project\\fed_tutorial_next\\client.py", line 97, in client_fn\n    return FlowerClient(\n           ^^^^^^^^^^^^^\n  File "J:\\Rehaan\'s College Project\\fed_tutorial_next\\client.py", line 22, in __init__\n    self.model = Net(num_classes)\n                 ^^^^^^^^^^^^^^^^\n  File "J:\\Rehaan\'s College Project\\fed_tutorial_next\\model.py", line 23, in __init__\n    self.conv1 = nn.Conv2d(3, 32, 3)\n    ^^^^^^^^^^\n  File "C:\\Users\\Guddu\\anaconda3\\envs\\capstone\\Lib\\site-packages\\torch\\nn\\modules\\module.py", line 1716, in __setattr__\n    raise AttributeError(\nAttributeError: cannot assign module before Module.__init__() call\n',)

[2024-03-06 20:49:19,325][flwr][ERROR] - [36mray::DefaultActor.run()[39m (pid=23928, ip=127.0.0.1, actor_id=a82a3640cc207c23333ef1b701000000, repr=<flwr.simulation.ray_transport.ray_actor.DefaultActor object at 0x000002360037C350>)
                                           ^^^^^^^^^^^^^^
  File "J:\Rehaan's College Project\fed_tutorial_next\client.py", line 97, in client_fn
    return FlowerClient(
           ^^^^^^^^^^^^^
  File "J:\Rehaan's College Project\fed_tutorial_next\client.py", line 22, in __init__
    self.model = Net(num_classes)
                 ^^^^^^^^^^^^^^^^
  File "J:\Rehaan's College Project\fed_tutorial_next\model.py", line 23, in __init__
    self.conv1 = nn.Conv2d(3, 32, 3)
    ^^^^^^^^^^
  File "C:\Users\Guddu\anaconda3\envs\capstone\Lib\site-packages\torch\nn\modules\module.py", line 1716, in __setattr__
    raise AttributeError(
AttributeError: cannot assign module before Module.__init__() call

The above exception was the direct cause of the following exception:

[36mray::DefaultActor.run()[39m (pid=23928, ip=127.0.0.1, actor_id=a82a3640cc207c23333ef1b701000000, repr=<flwr.simulation.ray_transport.ray_actor.DefaultActor object at 0x000002360037C350>)
  File "python\ray\_raylet.pyx", line 1807, in ray._raylet.execute_task
  File "python\ray\_raylet.pyx", line 1908, in ray._raylet.execute_task
  File "python\ray\_raylet.pyx", line 1813, in ray._raylet.execute_task
  File "python\ray\_raylet.pyx", line 1754, in ray._raylet.execute_task.function_executor
  File "C:\Users\Guddu\anaconda3\envs\capstone\Lib\site-packages\ray\_private\function_manager.py", line 726, in actor_method_executor
    return method(__ray_actor, *args, **kwargs)
           ^^^^^^^^^^^^^^^^^^^^^^^^^^^^^^^^^^^^
  File "C:\Users\Guddu\anaconda3\envs\capstone\Lib\site-packages\ray\util\tracing\tracing_helper.py", line 467, in _resume_span
    return method(self, *_args, **_kwargs)
           ^^^^^^^^^^^^^^^^^^^^^^^^^^^^^^^
  File "C:\Users\Guddu\anaconda3\envs\capstone\Lib\site-packages\flwr\simulation\ray_transport\ray_actor.py", line 90, in run
    raise ClientException(str(message)) from ex
flwr.simulation.ray_transport.ray_actor.ClientException: 
>>>>>>>A ClientException occurred.('\n\tSomething went wrong when running your client run.\n\tClient 12 crashed when the DefaultActor was running its run.\n\tException triggered on the client side: Traceback (most recent call last):\n  File "C:\\Users\\Guddu\\anaconda3\\envs\\capstone\\Lib\\site-packages\\flwr\\simulation\\ray_transport\\ray_actor.py", line 72, in run\n    client = check_clientfn_returns_client(client_fn(cid))\n                                           ^^^^^^^^^^^^^^\n  File "J:\\Rehaan\'s College Project\\fed_tutorial_next\\client.py", line 97, in client_fn\n    return FlowerClient(\n           ^^^^^^^^^^^^^\n  File "J:\\Rehaan\'s College Project\\fed_tutorial_next\\client.py", line 22, in __init__\n    self.model = Net(num_classes)\n                 ^^^^^^^^^^^^^^^^\n  File "J:\\Rehaan\'s College Project\\fed_tutorial_next\\model.py", line 23, in __init__\n    self.conv1 = nn.Conv2d(3, 32, 3)\n    ^^^^^^^^^^\n  File "C:\\Users\\Guddu\\anaconda3\\envs\\capstone\\Lib\\site-packages\\torch\\nn\\modules\\module.py", line 1716, in __setattr__\n    raise AttributeError(\nAttributeError: cannot assign module before Module.__init__() call\n',)
[2024-03-06 20:49:19,325][flwr][ERROR] - [36mray::DefaultActor.run()[39m (pid=23928, ip=127.0.0.1, actor_id=a82a3640cc207c23333ef1b701000000, repr=<flwr.simulation.ray_transport.ray_actor.DefaultActor object at 0x000002360037C350>)
                                           ^^^^^^^^^^^^^^
  File "J:\Rehaan's College Project\fed_tutorial_next\client.py", line 97, in client_fn
    return FlowerClient(
           ^^^^^^^^^^^^^
  File "J:\Rehaan's College Project\fed_tutorial_next\client.py", line 22, in __init__
    self.model = Net(num_classes)
                 ^^^^^^^^^^^^^^^^
  File "J:\Rehaan's College Project\fed_tutorial_next\model.py", line 23, in __init__
    self.conv1 = nn.Conv2d(3, 32, 3)
    ^^^^^^^^^^
  File "C:\Users\Guddu\anaconda3\envs\capstone\Lib\site-packages\torch\nn\modules\module.py", line 1716, in __setattr__
    raise AttributeError(
AttributeError: cannot assign module before Module.__init__() call

The above exception was the direct cause of the following exception:

[36mray::DefaultActor.run()[39m (pid=23928, ip=127.0.0.1, actor_id=a82a3640cc207c23333ef1b701000000, repr=<flwr.simulation.ray_transport.ray_actor.DefaultActor object at 0x000002360037C350>)
  File "python\ray\_raylet.pyx", line 1807, in ray._raylet.execute_task
  File "python\ray\_raylet.pyx", line 1908, in ray._raylet.execute_task
  File "python\ray\_raylet.pyx", line 1813, in ray._raylet.execute_task
  File "python\ray\_raylet.pyx", line 1754, in ray._raylet.execute_task.function_executor
  File "C:\Users\Guddu\anaconda3\envs\capstone\Lib\site-packages\ray\_private\function_manager.py", line 726, in actor_method_executor
    return method(__ray_actor, *args, **kwargs)
           ^^^^^^^^^^^^^^^^^^^^^^^^^^^^^^^^^^^^
  File "C:\Users\Guddu\anaconda3\envs\capstone\Lib\site-packages\ray\util\tracing\tracing_helper.py", line 467, in _resume_span
    return method(self, *_args, **_kwargs)
           ^^^^^^^^^^^^^^^^^^^^^^^^^^^^^^^
  File "C:\Users\Guddu\anaconda3\envs\capstone\Lib\site-packages\flwr\simulation\ray_transport\ray_actor.py", line 90, in run
    raise ClientException(str(message)) from ex
flwr.simulation.ray_transport.ray_actor.ClientException: 
>>>>>>>A ClientException occurred.('\n\tSomething went wrong when running your client run.\n\tClient 12 crashed when the DefaultActor was running its run.\n\tException triggered on the client side: Traceback (most recent call last):\n  File "C:\\Users\\Guddu\\anaconda3\\envs\\capstone\\Lib\\site-packages\\flwr\\simulation\\ray_transport\\ray_actor.py", line 72, in run\n    client = check_clientfn_returns_client(client_fn(cid))\n                                           ^^^^^^^^^^^^^^\n  File "J:\\Rehaan\'s College Project\\fed_tutorial_next\\client.py", line 97, in client_fn\n    return FlowerClient(\n           ^^^^^^^^^^^^^\n  File "J:\\Rehaan\'s College Project\\fed_tutorial_next\\client.py", line 22, in __init__\n    self.model = Net(num_classes)\n                 ^^^^^^^^^^^^^^^^\n  File "J:\\Rehaan\'s College Project\\fed_tutorial_next\\model.py", line 23, in __init__\n    self.conv1 = nn.Conv2d(3, 32, 3)\n    ^^^^^^^^^^\n  File "C:\\Users\\Guddu\\anaconda3\\envs\\capstone\\Lib\\site-packages\\torch\\nn\\modules\\module.py", line 1716, in __setattr__\n    raise AttributeError(\nAttributeError: cannot assign module before Module.__init__() call\n',)
[2024-03-06 20:49:19,329][flwr][ERROR] - Traceback (most recent call last):
  File "C:\Users\Guddu\anaconda3\envs\capstone\Lib\site-packages\flwr\simulation\app.py", line 308, in start_simulation
    hist = run_fl(
           ^^^^^^^
  File "C:\Users\Guddu\anaconda3\envs\capstone\Lib\site-packages\flwr\server\app.py", line 225, in run_fl
    hist = server.fit(num_rounds=config.num_rounds, timeout=config.round_timeout)
           ^^^^^^^^^^^^^^^^^^^^^^^^^^^^^^^^^^^^^^^^^^^^^^^^^^^^^^^^^^^^^^^^^^^^^^
  File "C:\Users\Guddu\anaconda3\envs\capstone\Lib\site-packages\flwr\server\server.py", line 90, in fit
    self.parameters = self._get_initial_parameters(timeout=timeout)
                      ^^^^^^^^^^^^^^^^^^^^^^^^^^^^^^^^^^^^^^^^^^^^^
  File "C:\Users\Guddu\anaconda3\envs\capstone\Lib\site-packages\flwr\server\server.py", line 279, in _get_initial_parameters
    get_parameters_res = random_client.get_parameters(ins=ins, timeout=timeout)
                         ^^^^^^^^^^^^^^^^^^^^^^^^^^^^^^^^^^^^^^^^^^^^^^^^^^^^^^
  File "C:\Users\Guddu\anaconda3\envs\capstone\Lib\site-packages\flwr\simulation\ray_transport\ray_client_proxy.py", line 196, in get_parameters
    res = self._submit_job(get_parameters, timeout)
          ^^^^^^^^^^^^^^^^^^^^^^^^^^^^^^^^^^^^^^^^^
  File "C:\Users\Guddu\anaconda3\envs\capstone\Lib\site-packages\flwr\simulation\ray_transport\ray_client_proxy.py", line 163, in _submit_job
    raise ex
  File "C:\Users\Guddu\anaconda3\envs\capstone\Lib\site-packages\flwr\simulation\ray_transport\ray_client_proxy.py", line 151, in _submit_job
    res, updated_context = self.actor_pool.get_client_result(self.cid, timeout)
                           ^^^^^^^^^^^^^^^^^^^^^^^^^^^^^^^^^^^^^^^^^^^^^^^^^^^^
  File "C:\Users\Guddu\anaconda3\envs\capstone\Lib\site-packages\flwr\simulation\ray_transport\ray_actor.py", line 425, in get_client_result
    return self._fetch_future_result(cid)
           ^^^^^^^^^^^^^^^^^^^^^^^^^^^^^^
  File "C:\Users\Guddu\anaconda3\envs\capstone\Lib\site-packages\flwr\simulation\ray_transport\ray_actor.py", line 306, in _fetch_future_result
    res_cid, res, updated_context = ray.get(
                                    ^^^^^^^^
  File "C:\Users\Guddu\anaconda3\envs\capstone\Lib\site-packages\ray\_private\auto_init_hook.py", line 22, in auto_init_wrapper
    return fn(*args, **kwargs)
           ^^^^^^^^^^^^^^^^^^^
  File "C:\Users\Guddu\anaconda3\envs\capstone\Lib\site-packages\ray\_private\client_mode_hook.py", line 103, in wrapper
    return func(*args, **kwargs)
           ^^^^^^^^^^^^^^^^^^^^^
  File "C:\Users\Guddu\anaconda3\envs\capstone\Lib\site-packages\ray\_private\worker.py", line 2624, in get
    raise value.as_instanceof_cause()
ray.exceptions.RayTaskError(ClientException): [36mray::DefaultActor.run()[39m (pid=23928, ip=127.0.0.1, actor_id=a82a3640cc207c23333ef1b701000000, repr=<flwr.simulation.ray_transport.ray_actor.DefaultActor object at 0x000002360037C350>)
                                           ^^^^^^^^^^^^^^
  File "J:\Rehaan's College Project\fed_tutorial_next\client.py", line 97, in client_fn
    return FlowerClient(
           ^^^^^^^^^^^^^
  File "J:\Rehaan's College Project\fed_tutorial_next\client.py", line 22, in __init__
    self.model = Net(num_classes)
                 ^^^^^^^^^^^^^^^^
  File "J:\Rehaan's College Project\fed_tutorial_next\model.py", line 23, in __init__
    self.conv1 = nn.Conv2d(3, 32, 3)
    ^^^^^^^^^^
  File "C:\Users\Guddu\anaconda3\envs\capstone\Lib\site-packages\torch\nn\modules\module.py", line 1716, in __setattr__
    raise AttributeError(
AttributeError: cannot assign module before Module.__init__() call

The above exception was the direct cause of the following exception:

[36mray::DefaultActor.run()[39m (pid=23928, ip=127.0.0.1, actor_id=a82a3640cc207c23333ef1b701000000, repr=<flwr.simulation.ray_transport.ray_actor.DefaultActor object at 0x000002360037C350>)
  File "python\ray\_raylet.pyx", line 1807, in ray._raylet.execute_task
  File "python\ray\_raylet.pyx", line 1908, in ray._raylet.execute_task
  File "python\ray\_raylet.pyx", line 1813, in ray._raylet.execute_task
  File "python\ray\_raylet.pyx", line 1754, in ray._raylet.execute_task.function_executor
  File "C:\Users\Guddu\anaconda3\envs\capstone\Lib\site-packages\ray\_private\function_manager.py", line 726, in actor_method_executor
    return method(__ray_actor, *args, **kwargs)
           ^^^^^^^^^^^^^^^^^^^^^^^^^^^^^^^^^^^^
  File "C:\Users\Guddu\anaconda3\envs\capstone\Lib\site-packages\ray\util\tracing\tracing_helper.py", line 467, in _resume_span
    return method(self, *_args, **_kwargs)
           ^^^^^^^^^^^^^^^^^^^^^^^^^^^^^^^
  File "C:\Users\Guddu\anaconda3\envs\capstone\Lib\site-packages\flwr\simulation\ray_transport\ray_actor.py", line 90, in run
    raise ClientException(str(message)) from ex
flwr.simulation.ray_transport.ray_actor.ClientException: 
>>>>>>>A ClientException occurred.('\n\tSomething went wrong when running your client run.\n\tClient 12 crashed when the DefaultActor was running its run.\n\tException triggered on the client side: Traceback (most recent call last):\n  File "C:\\Users\\Guddu\\anaconda3\\envs\\capstone\\Lib\\site-packages\\flwr\\simulation\\ray_transport\\ray_actor.py", line 72, in run\n    client = check_clientfn_returns_client(client_fn(cid))\n                                           ^^^^^^^^^^^^^^\n  File "J:\\Rehaan\'s College Project\\fed_tutorial_next\\client.py", line 97, in client_fn\n    return FlowerClient(\n           ^^^^^^^^^^^^^\n  File "J:\\Rehaan\'s College Project\\fed_tutorial_next\\client.py", line 22, in __init__\n    self.model = Net(num_classes)\n                 ^^^^^^^^^^^^^^^^\n  File "J:\\Rehaan\'s College Project\\fed_tutorial_next\\model.py", line 23, in __init__\n    self.conv1 = nn.Conv2d(3, 32, 3)\n    ^^^^^^^^^^\n  File "C:\\Users\\Guddu\\anaconda3\\envs\\capstone\\Lib\\site-packages\\torch\\nn\\modules\\module.py", line 1716, in __setattr__\n    raise AttributeError(\nAttributeError: cannot assign module before Module.__init__() call\n',)

[2024-03-06 20:49:19,331][flwr][ERROR] - Your simulation crashed :(. This could be because of several reasons. The most common are: 
	 > Sometimes, issues in the simulation code itself can cause crashes. It's always a good idea to double-check your code for any potential bugs or inconsistencies that might be contributing to the problem. For example: 
		 - You might be using a class attribute in your clients that hasn't been defined.
		 - There could be an incorrect method call to a 3rd party library (e.g., PyTorch).
		 - The return types of methods in your clients/strategies might be incorrect.
	 > Your system couldn't fit a single VirtualClient: try lowering `client_resources`.
	 > All the actors in your pool crashed. This could be because: 
		 - You clients hit an out-of-memory (OOM) error and actors couldn't recover from it. Try launching your simulation with more generous `client_resources` setting (i.e. it seems {'num_cpus': 1, 'num_gpus': 0.0} is not enough for your run). Use fewer concurrent actors. 
		 - You were running a multi-node simulation and all worker nodes disconnected. The head node might still be alive but cannot accommodate any actor with resources: {'num_cpus': 1, 'num_gpus': 0.0}.
Take a look at the Flower simulation examples for guidance <https://flower.dev/docs/framework/how-to-run-simulations.html>.
